Workbook
Name UPDATE: #REF!

Sheet ASSUMPTIONS
C1: By : Rahul B
C2: Batch 9
B7: Particulars (Rs in Crores) | C7: 2021A | D7: 2022A | E7: 2023A | F7: 2024A | G7: 2025A | H7: 2026F | I7: 2027F | J7: 2028F | K7: 2029F | L7: 2030F
B9: Sale of products | C9: =138204.61/100 -> 1382.0461 | D9: =200368.33/100 -> 2003.6833 | E9: =256419.67/100 -> 2564.1967 | F9: =271075.8/100 -> 2710.758 | G9: 3506.79 | H9: =G9*(1+$H$10) -> 4512.1834 | I9: =H9*(1+$H$10) -> 5805.8221 | J9: =I9*(1+$H$10) -> 7470.3459 | K9: =J9*(1+$H$10) -> 9612.0871 | L9: =K9*(1+$H$10) -> 12367.863
D10: =D9/C9-1 -> 0.44979484 | E10: =E9/D9-1 -> 0.27974151 | F10: =F9/E9-1 -> 0.057156809 | G10: =G9/F9-1 -> 0.29365661 | H10: =MEDIAN(D10:G10) -> 0.28669906
B11: Trading of goods | C11: =23.31 /100 -> 0.2331 | D11: =1196.77/100 -> 11.9677 | E11: =391.33/100 -> 3.9133 | F11: 0 | G11: 0 | H11: 0 | I11: 0 | J11: 0 | K11: 0 | L11: 0
D12: =D11/C11-1 -> 50.341484 | E12: =E11/D11-1 -> -0.67301152 | F12: 0 | G12: 0 | H12: 0 | I12: 0 | J12: 0 | K12: 0 | L12: 0
B13: Sale of services | C13: =46.99/100 -> 0.4699 | D13: =1971.38/100 -> 19.7138 | E13: =2403.97/100 -> 24.0397 | F13: =3444.83/100 -> 34.4483 | G13: 47.94 | H13: =G13+(1+$H$14) -> 49.331651 | I13: =H13+(1+$H$14) -> 50.723301 | J13: =I13+(1+$H$14) -> 52.114952 | K13: =J13+(1+$H$14) -> 53.506603 | L13: =K13+(1+$H$14) -> 54.898253
D14: =D13/C13-1 -> 40.953182 | E14: =E13/D13-1 -> 0.21943512 | F14: =F13/E13-1 -> 0.43297545 | G14: =G13/F13-1 -> 0.39165068 | H14: =MEDIAN(E14:G14) -> 0.39165068
B15: Export incentive | C15: =213.16/100 -> 2.1316 | D15: =188.81/100 -> 1.8881 | E15: =203.99/100 -> 2.0399 | F15: =217.58/100 -> 2.1758 | G15: 3.22 | H15: =G15+(1+$H$16) -> 4.3003983 | I15: =H15+(1+$H$16) -> 5.3807966 | J15: =I15+(1+$H$16) -> 6.4611949 | K15: =J15+(1+$H$16) -> 7.5415931 | L15: =K15+(1+$H$16) -> 8.6219914
D16: =D15/C15-1 -> -0.11423344 | E16: =E15/D15-1 -> 0.080398284 | F16: =F15/E15-1 -> 0.066620913 | G16: =G15/F15-1 -> 0.47991543 | H16: =MEDIAN(E16:G16) -> 0.080398284
B17: Scrap sales | C17: =118.07 /100 -> 1.1807 | D17: =178.16/100 -> 1.7816 | E17: =326.72/100 -> 3.2672 | F17: =389.97/100 -> 3.8997 | G17: 5.45 | H17: =G17+(1+$H$18) -> 6.7455671 | I17: =H17+(1+$H$18) -> 8.0411342 | J17: =I17+(1+$H$18) -> 9.3367014 | K17: =J17+(1+$H$18) -> 10.632268 | L17: =K17+(1+$H$18) -> 11.927836
D18: =D17/C17-1 -> 0.50893538 | E18: =E17/D17-1 -> 0.83385721 | F18: =F17/E17-1 -> 0.19359084 | G18: =G17/F17-1 -> 0.3975434 | H18: =MEDIAN(F18:G18) -> 0.29556712
B19: Trial charges | C19: =28.74/100 -> 0.2874 | D19: =107.04/100 -> 1.0704 | E19: =67.38/100 -> 0.6738 | F19: =343.07/100 -> 3.4307 | G19: 0.98 | H19: =G19*(1+$H$20) -> 0.44841874 | I19: =H19*(1+$H$20) -> 0.20518303 | J19: =I19*(1+$H$20) -> 0.093885629 | K19: =J19*(1+$H$20) -> 0.042959261 | L19: =K19*(1+$H$20) -> 0.019656875
D20: =D19/C19-1 -> 2.7244259 | E20: =E19/D19-1 -> -0.3705157 | F20: =F19/E19-1 -> 4.0915702 | G20: =G19/F19-1 -> -0.71434401 | H20: =MEDIAN(E20,G20) -> -0.54242985
B22: Revenue from Operations | C22: ='INCOME STATEMENT'!D8 -> 1386.3488 | D22: ='INCOME STATEMENT'!E8 -> 2040.1049 | E22: ='INCOME STATEMENT'!F8 -> 2598.1306 | F22: ='INCOME STATEMENT'!G8 -> 2754.7125 | G22: ='INCOME STATEMENT'!H8 -> 3564.38 | H22: =SUM(H9+H11+H13+H15+H17+H19) -> 4573.0094 | I22: =SUM(I9+I11+I13+I15+I17+I19) -> 5870.1726 | J22: =SUM(J9+J11+J13+J15+J17+J19) -> 7538.3526 | K22: =SUM(K9+K11+K13+K15+K17+K19) -> 9683.8105 | L22: =SUM(L9+L11+L13+L15+L17+L19) -> 12443.331
B24: ASSUMPTIONS FOR INCOME STATEMENT
B26: RFO | C26: =C22 -> 1386.3488 | D26: =D22 -> 2040.1049 | E26: =E22 -> 2598.1306 | F26: =F22 -> 2754.7125 | G26: =G22 -> 3564.38 | H26: =H22 -> 4573.0094 | I26: =I22 -> 5870.1726 | J26: =J22 -> 7538.3526 | ... L26: =L22 -> 12443.331
B27: Other Income | C27: ='INCOME STATEMENT'!D9 -> 2.6602 | D27: ='INCOME STATEMENT'!E9 -> 3.6867 | E27: ='INCOME STATEMENT'!F9 -> 4.5064 | F27: ='INCOME STATEMENT'!G9 -> 7.1674 | G27: ='INCOME STATEMENT'!H9 -> 14.55 | H27: =G27*(1+$H$28) -> 14.598626 | I27: =H27*(1+$H$28) -> 14.647414 | J27: =I27*(1+$H$28) -> 14.696365 | K27: =J27*(1+$H$28) -> 14.745479 | L27: =K27*(1+$H$28) -> 14.794758
B28: Other Income as % of RFO | C28: =C27/C26 -> 0.0019188533 | D28: =D27/D26 -> 0.001807113 | E28: =E27/E26 -> 0.0017344779 | F28: =F27/F26 -> 0.0026018686 | G28: =G27/G26 -> 0.0040820563 | H28: =MEDIAN(F28:G28) -> 0.0033419625
B30: COGS | C30: ='INCOME STATEMENT'!D12+'INCOME STATEMENT'!D13+'INCOME STATEMENT'!D14+'INCOME STATEMENT'!D18 -> 1248.4623 | D30: ='INCOME STATEMENT'!E12+'INCOME STATEMENT'!E13+'INCOME STATEMENT'!E14+'INCOME STATEMENT'!E18 -> 1857.6859 | E30: ='INCOME STATEMENT'!F12+'INCOME STATEMENT'!F13+'INCOME STATEMENT'!F14+'INCOME STATEMENT'!F18 -> 2338.1799 | F30: ='INCOME STATEMENT'!G12+'INCOME STATEMENT'!G13+'INCOME STATEMENT'!G14+'INCOME STATEMENT'!G18 -> 2405.8504 | G30: ='INCOME STATEMENT'!H12+'INCOME STATEMENT'!H13+'INCOME STATEMENT'!H14+'INCOME STATEMENT'!H18 -> 2975.57 | H30: =H26*$H$31 -> 3905.7279 | I30: =I26*$H$31 -> 5013.6124 | J30: =J26*$H$31 -> 6438.376 | K30: =K26*$H$31 -> 8270.7743 | L30: =L26*$H$31 -> 10627.633
B31: COGS as % of RFO | C31: =C30/C22 -> 0.90053982 | D31: =D30/D22 -> 0.91058352 | E31: =E30/E22 -> 0.89994702 | F31: =F30/F22 -> 0.87335807 | G31: =G30/G22 -> 0.83480718 | H31: =MEDIAN(F31:G31) -> 0.85408262
B33: Employee Benefit Expenses | C33: ='INCOME STATEMENT'!D15 -> 30.6021 | D33: ='INCOME STATEMENT'!E15 -> 40.8047 | E33: ='INCOME STATEMENT'!F15 -> 55.6058 | F33: ='INCOME STATEMENT'!G15 -> 82.6182 | G33: ='INCOME STATEMENT'!H15 -> 222.37 | H33: =H22*$H$34 -> 211.22345 | I33: =I22*$H$34 -> 271.13832 | J33: =J22*$H$34 -> 348.19015 | K33: =K22*$H$34 -> 447.28704 | L33: =L22*$H$34 -> 574.74697
B34: Employee Benefit Expense as % of RFO | C34: =C33/C26 -> 0.022073882 | D34: =D33/D26 -> 0.020001275 | E34: =E33/E26 -> 0.021402234 | F34: =F33/F26 -> 0.029991587 | G34: =G33/G26 -> 0.062386726 | H34: =MEDIAN(F34:G34) -> 0.046189157
B36: Other Expenses (Others) | C36: ='INCOME STATEMENT'!D19 -> 24.0477 | D36: ='INCOME STATEMENT'!E19 -> 26.7445 | E36: ='INCOME STATEMENT'!F19 -> 31.1351 | F36: ='INCOME STATEMENT'!G19 -> 44.5176 | G36: ='INCOME STATEMENT'!H19 -> 73.29 | H36: =H26*$H$37 -> 73.902233 | I36: =I26*$H$37 -> 94.86507 | J36: =J26*$H$37 -> 121.82374 | K36: =K26*$H$37 -> 156.49546 | L36: =L26*$H$37 -> 201.09076
B37: Other Expenses (Others) as % of RFO | C37: =C36/C26 -> 0.017346068 | D37: =D36/D26 -> 0.013109375 | E37: =E36/E26 -> 0.011983655 | F37: =F36/F26 -> 0.016160525 | G37: =G36/G26 -> 0.020561781 | H37: =MEDIAN(C37:G37) -> 0.016160525
B39: Profit Before Tax | C39: ='INCOME STATEMENT'!D23 -> 48.0663 | D39: ='INCOME STATEMENT'!E23 -> 71.4818 | E39: ='INCOME STATEMENT'!F23 -> 104.5091 | F39: ='INCOME STATEMENT'!G23 -> 117.4141 | G39: ='INCOME STATEMENT'!H23 -> 147.93 | H39: ='INCOME STATEMENT'!I23 -> 218.83221 | I39: ='INCOME STATEMENT'!J23 -> 270.37395 | J39: ='INCOME STATEMENT'!K23 -> 341.59615 | ... L39: ='INCOME STATEMENT'!M23 -> 551.16614
B40: Tax Expense (total tax) | C40: ='INCOME STATEMENT'!D30 -> 13.6691 | D40: ='INCOME STATEMENT'!E30 -> 26.8186 | E40: ='INCOME STATEMENT'!F30 -> 33.392 | F40: ='INCOME STATEMENT'!G30 -> 24.6887 | G40: ='INCOME STATEMENT'!H30 -> 38.29 | H40: =H39*$H$41 -> 51.328075 | I40: =I39*$H$41 -> 63.417422 | J40: =J39*$H$41 -> 80.122908 | K40: =K39*$H$41 -> 101.62275 | L40: =L39*$H$41 -> 129.27849
B41: Tax as % of PBT | C41: =C40/C39 -> 0.28438012 | D41: =D40/D39 -> 0.37518082 | E41: =E40/E39 -> 0.31951285 | F41: =F40/F39 -> 0.21027032 | G41: =G40/G39 -> 0.25883864 | H41: =MEDIAN(F41:G41) -> 0.23455448
B43: Profit for the Year (Total) | C43: ='INCOME STATEMENT'!D31 -> 34.3972 | D43: ='INCOME STATEMENT'!E31 -> 44.6632 | E43: ='INCOME STATEMENT'!F31 -> 71.1171 | F43: ='INCOME STATEMENT'!G31 -> 92.7254 | G43: ='INCOME STATEMENT'!H31 -> 109.64 | H43: =H39-H40 -> 167.50413 | I43: =I39-I40 -> 206.95653 | J43: =J39-J40 -> 261.47325 | K43: =K39-K40 -> 331.63589 | L43: =L39-L40 -> 421.88766
B46: ASSUMPTIONS FOR BALANCE SHEET
B48: COGS | C48: =C30 -> 1248.4623 | D48: =D30 -> 1857.6859 | E48: =E30 -> 2338.1799 | F48: =F30 -> 2405.8504 | G48: =G30 -> 2975.57 | H48: =H30 -> 3905.7279 | I48: =I30 -> 5013.6124 | J48: =J30 -> 6438.376 | ... L48: =L30 -> 10627.633
B49: Closing Inventory | C49: ='BALANCE SHEET'!C24 -> 169.0834 | D49: ='BALANCE SHEET'!D24 -> 237.7694 | E49: ='BALANCE SHEET'!E24 -> 333.9117 | F49: ='BALANCE SHEET'!F24 -> 493.4003 | G49: ='BALANCE SHEET'!G24 -> 752.82 | H49: =(H48*$H$51)/365 -> 988.1502 | I49: =(I48*$H$51)/365 -> 1268.4453 | J49: =(J48*$H$51)/365 -> 1628.9108 | K49: =(K48*$H$51)/365 -> 2092.5081 | L49: =(L48*$H$51)/365 -> 2688.7939
B50: Inventory Turn Over Ratio (COGS/Closing Inventory) | C50: =C48/C49 -> 7.3837071 | D50: =D48/D49 -> 7.812973 | E50: =E48/E49 -> 7.0023899 | F50: =F48/F49 -> 4.8760619 | G50: =G48/G49 -> 3.952565
B51: Inventories Days (Closing Inventory/COGS)*365 | C51: =365/C50 -> 49.433164 | D51: =365/D50 -> 46.717172 | E51: =365/E50 -> 52.125061 | F51: =365/F50 -> 74.85549 | G51: =365/G50 -> 92.345097 | H51: =G51 -> 92.345097
B53: RFO | C53: =C26 -> 1386.3488 | D53: =D26 -> 2040.1049 | E53: =E26 -> 2598.1306 | F53: =F26 -> 2754.7125 | G53: =G26 -> 3564.38 | H53: =H26 -> 4573.0094 | I53: =I26 -> 5870.1726 | J53: =J26 -> 7538.3526 | ... L53: =L26 -> 12443.331
B54: Closing Receivables. | C54: ='BALANCE SHEET'!C26 -> 49.6882 | D54: ='BALANCE SHEET'!D26 -> 72.1902 | E54: ='BALANCE SHEET'!E26 -> 104.4858 | F54: ='BALANCE SHEET'!F26 -> 175.774 | G54: ='BALANCE SHEET'!G26 -> 209.31 | H54: =(H53*$H$55)/365 -> 268.53944 | I54: =(I53*$H$55)/365 -> 344.71235 | J54: =(J53*$H$55)/365 -> 442.67238 | K54: =(K53*$H$55)/365 -> 568.65945 | L54: =(L53*$H$55)/365 -> 730.70594
B55: Trade Receivable Days (TR / RFO) * 365 | C55: =(365*C54)/C53 -> 13.081984 | D55: =(365*D54)/D53 -> 12.91572 | E55: =(365*E54)/E53 -> 14.678753 | F55: =(365*F54)/F53 -> 23.290093 | G55: =(365*G54)/G53 -> 21.433784 | H55: =G55 -> 21.433784
B57: COGS | C57: =C30 -> 1248.4623 | D57: =D30 -> 1857.6859 | E57: =E30 -> 2338.1799 | F57: =F30 -> 2405.8504 | G57: =G30 -> 2975.57 | H57: =H30 -> 3905.7279 | I57: =I30 -> 5013.6124 | J57: =J30 -> 6438.376 | ... L57: =L30 -> 10627.633
B58: Cl. Payables | C58: =SUM('BALANCE SHEET'!C55:C56) -> 213.8853 | D58: =SUM('BALANCE SHEET'!D55:D56) -> 271.1498 | E58: =SUM('BALANCE SHEET'!E55:E56) -> 335.3128 | F58: =SUM('BALANCE SHEET'!F55:F56) -> 425.8012 | G58: =SUM('BALANCE SHEET'!G55:G56) -> 523.97 | H58: =(H57*$H$59)/365 -> 691.25812 | I58: =(I57*$H$59)/365 -> 887.33787 | J58: =(J57*$H$59)/365 -> 1139.5007 | K58: =(K57*$H$59)/365 -> 1463.8091 | L58: =(L57*$H$59)/365 -> 1880.9394
...

Sheet INCOME STATEMENT
B6: Particulars (Rs in Crores) | D6: 2021A | E6: 2022A | F6: 2023A | G6: 2024A | H6: 2025A | I6: 2026F | J6: 2027F | K6: 2028F | L6: 2029F | M6: 2030F
B8: Revenue from operations | D8: =138634.88/100 -> 1386.3488 | E8: =204010.49/100 -> 2040.1049 | F8: =259813.06/100 -> 2598.1306 | G8: =275471.25/100 -> 2754.7125 | H8: 3564.38 | I8: =ASSUMPTIONS!H26 -> 4573.0094 | J8: =ASSUMPTIONS!I26 -> 5870.1726 | K8: =ASSUMPTIONS!J26 -> 7538.3526 | L8: =ASSUMPTIONS!K26 -> 9683.8105 | M8: =ASSUMPTIONS!L26 -> 12443.331
B9: Other income | D9: =266.02/100 -> 2.6602 | E9: =368.67/100 -> 3.6867 | F9: =450.64/100 -> 4.5064 | G9: =716.74/100 -> 7.1674 | H9: 14.55 | I9: =ASSUMPTIONS!H27 -> 14.598626 | J9: =ASSUMPTIONS!I27 -> 14.647414 | K9: =ASSUMPTIONS!J27 -> 14.696365 | L9: =ASSUMPTIONS!K27 -> 14.745479 | M9: =ASSUMPTIONS!L27 -> 14.794758
B10: Total Income | D10: =D8+D9 -> 1389.009 | E10: =E8+E9 -> 2043.7916 | F10: =F8+F9 -> 2602.637 | G10: =G8+G9 -> 2761.8799 | H10: =H8+H9 -> 3578.93 | I10: =SUM(I8:I9) -> 4587.6081 | J10: =SUM(J8:J9) -> 5884.82 | K10: =SUM(K8:K9) -> 7553.049 | L10: =SUM(L8:L9) -> 9698.556 | M10: =SUM(M8:M9) -> 12458.126
B12: Cost of material consumed | D12: =119989.95/100 -> 1199.8995 | E12: =180245.05/100 -> 1802.4505 | F12: =224429.87/100 -> 2244.2987 | G12: =233239.44/100 -> 2332.3944 | H12: 2829.24
B13: Purchase of stock-in-trade | D13: 0 | E13: =1135.18/100 -> 11.3518 | F13: =211.28/100 -> 2.1128 | G13: =57.89/100 -> 0.5789 | H13: 0.61
B14: Changes in inventories of finished goods, stock-in-trade and work-in progress | D14: =-925.84/100 -> -9.2584 | E14: =-3569.3/100 -> -35.693 | F14: =-1419.54/100 -> -14.1954 | G14: =-5983.16/100 -> -59.8316 | H14: -37.8 | I14: =ASSUMPTIONS!H30 -> 3905.7279 | J14: =ASSUMPTIONS!I30 -> 5013.6124 | K14: =ASSUMPTIONS!J30 -> 6438.376 | L14: =ASSUMPTIONS!K30 -> 8270.7743 | M14: =ASSUMPTIONS!L30 -> 10627.633
B15: Employee benefits expense | D15: =3060.21/100 -> 30.6021 | E15: =4080.47/100 -> 40.8047 | F15: =5560.58/100 -> 55.6058 | G15: =8261.82/100 -> 82.6182 | H15: 222.37 | I15: =ASSUMPTIONS!H33 -> 211.22345 | J15: =ASSUMPTIONS!I33 -> 271.13832 | K15: =ASSUMPTIONS!J33 -> 348.19015 | L15: =ASSUMPTIONS!K33 -> 447.28704 | M15: =ASSUMPTIONS!L33 -> 574.74697
B16: Finance costs | D16: =1867.66/100 -> 18.6766 | E16: =2024.1/100 -> 20.241 | F16: =3580.19/100 -> 35.8019 | G16: =5668.16/100 -> 56.6816 | H16: 80.04 | I16: ='DEBT SCHEDULE'!I13 -> 85.746167 | J16: ='DEBT SCHEDULE'!J13 -> 116.30229 | K16: ='DEBT SCHEDULE'!K13 -> 150.96163 | L16: ='DEBT SCHEDULE'!L13 -> 195.73845 | M16: ='DEBT SCHEDULE'!M13 -> 253.55251
B17: Depreciation and amortisation expenses | D17: =1719.56/100 -> 17.1956 | E17: =2450.88/100 -> 24.5088 | F17: =3740.52/100 -> 37.4052 | G17: =5479.8/100 -> 54.798 | H17: 79.73 | I17: ='FA SCHEDULE'!H16+'FA SCHEDULE'!H26 -> 92.176103 | J17: ='FA SCHEDULE'!I16+'FA SCHEDULE'!I26 -> 118.52795 | K17: ='FA SCHEDULE'!J16+'FA SCHEDULE'!J26 -> 152.10133 | L17: ='FA SCHEDULE'!K16+'FA SCHEDULE'!K26 -> 195.0021 | M17: ='FA SCHEDULE'!L16+'FA SCHEDULE'!L26 -> 249.93659
B18: Manufacturing and operating costs | D18: =5782.12/100 -> 57.8212 | E18: =7957.66/100 -> 79.5766 | F18: =10596.38/100 -> 105.9638 | G18: =13270.87/100 -> 132.7087 | H18: 183.52
B19: Other expenses | D19: =2404.77/100 -> 24.0477 | E19: =2674.45/100 -> 26.7445 | F19: =3113.51/100 -> 31.1351 | G19: =4451.76/100 -> 44.5176 | H19: 73.29 | I19: =ASSUMPTIONS!H36 -> 73.902233 | J19: =ASSUMPTIONS!I36 -> 94.86507 | K19: =ASSUMPTIONS!J36 -> 121.82374 | L19: =ASSUMPTIONS!K36 -> 156.49546 | M19: =ASSUMPTIONS!L36 -> 201.09076
B20: Total Expenses | D20: =SUM(D12:D19) -> 1338.9843 | E20: =SUM(E12:E19) -> 1969.9849 | F20: =SUM(F12:F19) -> 2498.1279 | G20: =SUM(G12:G19) -> 2644.4658 | H20: =SUM(H12:H19) -> 3431 | I20: =SUM(I14:I19) -> 4368.7759 | J20: =SUM(J14:J19) -> 5614.446 | K20: =SUM(K14:K19) -> 7211.4528 | L20: =SUM(L14:L19) -> 9265.2973 | M20: =SUM(M14:M19) -> 11906.96
B21: Share of loss from associate | D21: =-195.84/100 -> -1.9584 | E21: =-232.49/100 -> -2.3249 | F21: 0 | G21: 0 | H21: 0
B23: Profit before tax | D23: =D10-D20+D21 -> 48.0663 | E23: =E10-E20+E21 -> 71.4818 | F23: =F10-F20+F21 -> 104.5091 | G23: =G10-G20+G21 -> 117.4141 | H23: =H10-H20+H21 -> 147.93 | I23: =I10-I20 -> 218.83221 | J23: =J10-J20 -> 270.37395 | K23: =K10-K20 -> 341.59615 | L23: =L10-L20 -> 433.25864 | M23: =M10-M20 -> 551.16614
B25: Current tax | D25: =884.93/100 -> 8.8493 | E25: =1337.63/100 -> 13.3763 | F25: =3153.24/100 -> 31.5324 | G25: =2987.38/100 -> 29.8738 | H25: 37.57 | I25: =ASSUMPTIONS!H40 -> 51.328075 | J25: =ASSUMPTIONS!I40 -> 63.417422 | K25: =ASSUMPTIONS!J40 -> 80.122908 | L25: =ASSUMPTIONS!K40 -> 101.62275 | M25: =ASSUMPTIONS!L40 -> 129.27849
B26: Tax under MAT | D26: =89.28/100 -> 0.8928 | E26: =603.68 /100 -> 6.0368 | F26: 0 | G26: 0 | H26: 0
B27: Deferred tax (excluding MAT credit entitlement/ utilisation only In 2024) | D27: =785.85/100 -> 7.8585 | E27: =740.55/100 -> 7.4055 | F27: =367.03/100 -> 3.6703 | G27: =-533.1/100 -> -5.331 | H27: 0.72
B28: Tax adjustments pertaining to previous years | D28: =-393.15/100 -> -3.9315 | E28: 0 | F28: =-181.07/100 -> -1.8107 | G28: =(14.59)/100 -> 0.1459 | H28: 0
B30: Total Tax | D30: =SUM(D25:D28) -> 13.6691 | E30: =SUM(E25:E28) -> 26.8186 | F30: =SUM(F25:F28) -> 33.392 | G30: =SUM(G25:G28) -> 24.6887 | H30: =SUM(H25:H28) -> 38.29 | I30: =ASSUMPTIONS!H40 -> 51.328075 | J30: =ASSUMPTIONS!I40 -> 63.417422 | K30: =ASSUMPTIONS!J40 -> 80.122908 | L30: =ASSUMPTIONS!K40 -> 101.62275 | M30: =ASSUMPTIONS!L40 -> 129.27849
B31: Profit for the year | D31: =D23-D30 -> 34.3972 | E31: =E23-E30 -> 44.6632 | F31: =F23-F30 -> 71.1171 | G31: =G23-G30 -> 92.7254 | H31: =H23-H30 -> 109.64 | I31: =ASSUMPTIONS!H43 -> 167.50413 | J31: =ASSUMPTIONS!I43 -> 206.95653 | K31: =ASSUMPTIONS!J43 -> 261.47325 | L31: =ASSUMPTIONS!K43 -> 331.63589 | M31: =ASSUMPTIONS!L43 -> 421.88766
B34: No. of Equity Shares (in crores, FV ₹2 post 1:5 split in FY23) | D34: 10.6 | E34: 11.25 | F34: 11.27 | G34: 11.46 | H34: 11.75 | I34: =H34 -> 11.75 | J34: =I34 -> 11.75 | K34: =J34 -> 11.75 | L34: =K34 -> 11.75 | M34: =L34 -> 11.75
B36: Earnings per equity share | D36: =D31/D34 -> 3.2450189 | E36: =E31/E34 -> 3.9700622 | F36: =F31/F34 -> 6.3103017 | G36: =G31/G34 -> 8.0912216 | H36: =H31/H34 -> 9.3310638 | I36: =I31/I34 -> 14.255671 | J36: =J31/J34 -> 17.613322 | K36: =K31/K34 -> 22.253042 | ... M36: =M31/M34 -> 35.905332
D38: =D23+D17+D16 -> 83.9385 | E38: =E23+E17+E16 -> 116.2316 | F38: =F23+F17+F16 -> 177.7162 | G38: =G23+G17+G16 -> 228.8937 | H38: =H23+H17+H16 -> 307.7 | I38: =I23+I17+I16 -> 396.75448 | J38: =J23+J17+J16 -> 505.2042 | K38: =K23+K17+K16 -> 644.65911 | ... M38: =M23+M17+M16 -> 1054.6552
B39: Interest Coverage Ratio | D39: =D38/D16 -> 4.4943137 | E39: =E38/E16 -> 5.7423843 | F39: =F38/F16 -> 4.9638762 | G39: =G38/G16 -> 4.0382364 | H39: =H38/H16 -> 3.8443278 | I39: =I38/I16 -> 4.6270812 | J39: =J38/J16 -> 4.3438887 | K39: =K38/K16 -> 4.2703508 | ... M39: =M38/M16 -> 4.1595141

Sheet BALANCE SHEET
B6: Particulars (Rs in Crores) | C6: 2021A | D6: 2022A | E6: 2023A | F6: 2024A | G6: 2025A | H6: 2026F | I6: 2027F | J6: 2028F | K6: 2029F | L6: 2030F
B7: ASSETS
B8: Non-current assets
B9: Property, plant and equipment | C9: =27034.68/100 -> 270.3468 | D9: =39461.48/100 -> 394.6148 | E9: =51965.63/100 -> 519.6563 | F9: =84686.57/100 -> 846.8657 | G9: 928.52 | H9: ='FA SCHEDULE'!H17 -> 1200.5451 | I9: ='FA SCHEDULE'!I17 -> 1541.0873 | J9: ='FA SCHEDULE'!J17 -> 1979.032 | K9: ='FA SCHEDULE'!K17 -> 2542.2758 | L9: ='FA SCHEDULE'!L17 -> 3266.7284
B10: Right of use assets | C10: 0 | D10: =3232.67/100 -> 32.3267 | E10: =3095.65/100 -> 30.9565 | F10: =5386.84/100 -> 53.8684 | G10: 68.99 | H10: =G10 -> 68.99 | I10: =H10 -> 68.99 | J10: =I10 -> 68.99 | K10: =J10 -> 68.99 | L10: =K10 -> 68.99
B11: Capital work-in-progress | C11: =5346.83/100 -> 53.4683 | D11: =8716.12/100 -> 87.1612 | E11: =12472.47/100 -> 124.7247 | F11: =840.25/100 -> 8.4025 | G11: 119.11 | H11: =G11 -> 119.11 | I11: =H11 -> 119.11 | J11: =I11 -> 119.11 | K11: =J11 -> 119.11 | L11: =K11 -> 119.11
B12: Goodwill | C12: 0 | D12: 0 | E12: =301.62/100 -> 3.0162 | F12: =652.15/100 -> 6.5215 | G12: 6.52 | H12: =G12 -> 6.52 | I12: =H12 -> 6.52 | J12: =I12 -> 6.52 | K12: =J12 -> 6.52 | L12: =K12 -> 6.52
B13: Other intangible assets | C13: =51.09/100 -> 0.5109 | D13: =6.7/100 -> 0.067 | E13: =4.36/100 -> 0.0436 | F13: =111.96/100 -> 1.1196 | G13: 8.03 | H13: ='FA SCHEDULE'!H27 -> 14.98032 | I13: ='FA SCHEDULE'!I27 -> 20.751208 | J13: ='FA SCHEDULE'!J27 -> 25.835411 | K13: ='FA SCHEDULE'!K27 -> 30.314639 | L13: ='FA SCHEDULE'!L27 -> 34.260877
B14: Intangible assets under development | C14: 0 | D14: 0 | E14: =39.95/100 -> 0.3995 | F14: =33.68 /100 -> 0.3368 | G14: 0.4 | H14: =G14 -> 0.4 | I14: =H14 -> 0.4 | J14: =I14 -> 0.4 | K14: =J14 -> 0.4 | L14: =K14 -> 0.4
B15: Financial assets - Investments (Non-current) | C15: 0 | D15: 0 | E15: 0 | F15: 0 | G15: 0 | H15: =G15 -> 0 | I15: =H15 -> 0 | J15: =I15 -> 0 | K15: =J15 -> 0 | L15: =K15 -> 0
B16: Financial assets - Loans (Non-current) | C16: =276.26/100 -> 2.7626 | D16: 0 | E16: 0 | F16: 0 | G16: 0 | H16: =G16 -> 0 | I16: =H16 -> 0 | J16: =I16 -> 0 | K16: =J16 -> 0 | L16: =K16 -> 0
B17: Financial assets - Other financial assets (Non-current) | C17: =40.88/100 -> 0.4088 | D17: =669.1 /100 -> 6.691 | E17: =1896.21/100 -> 18.9621 | F17: =12464.54/100 -> 124.6454 | G17: 37.41 | H17: =G17 -> 37.41 | I17: =H17 -> 37.41 | J17: =I17 -> 37.41 | K17: =J17 -> 37.41 | L17: =K17 -> 37.41
B18: Deferred tax asset (net) | C18: 0 | D18: 0 | E18: =42.53/100 -> 0.4253 | F18: =75.65/100 -> 0.7565 | G18: 7.88 | H18: =G18 -> 7.88 | I18: =H18 -> 7.88 | J18: =I18 -> 7.88 | K18: =J18 -> 7.88 | L18: =K18 -> 7.88
B19: Non-current tax assets (net) | C19: =1100.34/100 -> 11.0034 | D19: =1735.79 /100 -> 17.3579 | E19: =1368.78/100 -> 13.6878 | F19: =374.39/100 -> 3.7439 | G19: 0.8 | H19: =G19 -> 0.8 | I19: =H19 -> 0.8 | J19: =I19 -> 0.8 | K19: =J19 -> 0.8 | L19: =K19 -> 0.8
B20: Other non-current assets | C20: =1119.4/100 -> 11.194 | D20: =789.34 /100 -> 7.8934 | E20: =2563.1/100 -> 25.631 | F20: =1145.53/100 -> 11.4553 | G20: 47.9 | H20: =G20 -> 47.9 | I20: =H20 -> 47.9 | J20: =I20 -> 47.9 | K20: =J20 -> 47.9 | L20: =K20 -> 47.9
B21: Total non-current assets | C21: =SUM(C9:C20) -> 349.6948 | D21: =SUM(D9:D20) -> 546.112 | E21: =SUM(E9:E20) -> 737.503 | F21: =SUM(F9:F20) -> 1057.7156 | G21: =SUM(G9:G20) -> 1225.56 | H21: =SUM(H9:H20) -> 1504.5354 | I21: =SUM(I9:I20) -> 1850.8485 | J21: =SUM(J9:J20) -> 2293.8774 | ... L21: =SUM(L9:L20) -> 3589.9993
B23: Current assets
B24: Inventories | C24: =16908.34/100 -> 169.0834 | D24: =23776.94/100 -> 237.7694 | E24: =33391.17/100 -> 333.9117 | F24: =49340.03/100 -> 493.4003 | G24: 752.82 | H24: =ASSUMPTIONS!H49 -> 988.1502 | I24: =ASSUMPTIONS!I49 -> 1268.4453 | J24: =ASSUMPTIONS!J49 -> 1628.9108 | K24: =ASSUMPTIONS!K49 -> 2092.5081 | L24: =ASSUMPTIONS!L49 -> 2688.7939
B25: Financial assets - Investments (Current) | C25: =41.27 /100 -> 0.4127 | D25: 0 | E25: 0 | F25: 0 | G25: 0 | H25: =G25 -> 0 | I25: =H25 -> 0 | J25: =I25 -> 0 | K25: =J25 -> 0 | L25: =K25 -> 0
B26: Trade receivables | C26: =4968.82/100 -> 49.6882 | D26: =7219.02/100 -> 72.1902 | E26: =10448.58/100 -> 104.4858 | F26: =17577.4/100 -> 175.774 | G26: 209.31 | H26: =ASSUMPTIONS!H54 -> 268.53944 | I26: =ASSUMPTIONS!I54 -> 344.71235 | J26: =ASSUMPTIONS!J54 -> 442.67238 | K26: =ASSUMPTIONS!K54 -> 568.65945 | L26: =ASSUMPTIONS!L54 -> 730.70594
B27: Cash and cash equivalents | C27: =4443.86/100 -> 44.4386 | D27: =3259.75/100 -> 32.5975 | E27: =3986.92/100 -> 39.8692 | F27: =4318.09/100 -> 43.1809 | G27: 76.99 | H27: =CFS!I28 -> 182.92038 | I27: =CFS!J28 -> 234.8069 | J27: =CFS!K28 -> 301.53411 | K27: =CFS!L28 -> 387.35242 | L27: =CFS!M28 -> 497.73325
B28: Bank balances other than cash and cash equivalents | C28: =1409.49/100 -> 14.0949 | D28: =1079.9/100 -> 10.799 | E28: =1059.65/100 -> 10.5965 | F28: =610.82/100 -> 6.1082 | G28: 6.63 | H28: =G28 -> 6.63 | I28: =H28 -> 6.63 | J28: =I28 -> 6.63 | K28: =J28 -> 6.63 | L28: =K28 -> 6.63
B29: Financial assets - Loans (Current) | C29: =898.87/100 -> 8.9887 | D29: 0 | E29: 0 | F29: 0 | G29: 1 | H29: =G29 -> 1 | I29: =H29 -> 1 | J29: =I29 -> 1 | K29: =J29 -> 1 | L29: =K29 -> 1
B30: Financial assets - Other financial assets (Current) | C30: =1389.31/100 -> 13.8931 | D30: =3265.55/100 -> 32.6555 | E30: =5133.12/100 -> 51.3312 | F30: =7807.2/100 -> 78.072 | G30: 157.14 | H30: =G30 -> 157.14 | I30: =H30 -> 157.14 | J30: =I30 -> 157.14 | K30: =J30 -> 157.14 | L30: =K30 -> 157.14
B31: Other current assets | C31: =4412.64/100 -> 44.1264 | D31: =5422.7/100 -> 54.227 | E31: =5748.71/100 -> 57.4871 | F31: =7099.59/100 -> 70.9959 | G31: 61.08 | H31: =ASSUMPTIONS!H68 -> 109.52096 | I31: =ASSUMPTIONS!I68 -> 140.58728 | J31: =ASSUMPTIONS!J68 -> 180.53924 | K31: =ASSUMPTIONS!K68 -> 231.92173 | L31: =ASSUMPTIONS!L68 -> 298.01068
B32: Total current assets | C32: =SUM(C24:C31) -> 344.726 | D32: =SUM(D24:D31) -> 440.2386 | E32: =SUM(E24:E31) -> 597.6815 | F32: =SUM(F24:F31) -> 867.5313 | G32: =SUM(G24:G31) -> 1264.97 | H32: =SUM(H24:H31) -> 1713.901 | I32: =SUM(I24:I31) -> 2153.3218 | J32: =SUM(J24:J31) -> 2718.4266 | ... L32: =SUM(L24:L31) -> 4380.0138
B34: Total assets | C34: =C21+C32 -> 694.4208 | D34: =D21+D32 -> 986.3506 | E34: =E21+E32 -> 1335.1845 | F34: =F21+F32 -> 1925.2469 | G34: =G21+G32 -> 2490.53 | H34: =H21+H32 -> 3218.4364 | I34: =I21+I32 -> 4004.1703 | J34: =J21+J32 -> 5012.304 | ... L34: =L21+L32 -> 7970.0131
B36: EQUITY AND LIABILITIES
B37: Equity
B38: Equity share capital | C38: =2119.81/100 -> 21.1981 | D38: =2254.86 /100 -> 22.5486 | E38: =2254.86/100 -> 22.5486 | F38: =2291.47/100 -> 22.9147 | G38: 23.5 | H38: =G38 -> 23.5 | I38: =H38 -> 23.5 | J38: =I38 -> 23.5 | K38: =J38 -> 23.5 | L38: =K38 -> 23.5
B39: Instrument entirely equity in nature | C39: 0 | D39: 0 | E39: 0 | F39: 0 | G39: 3.56 | H39: =G39 -> 3.56 | I39: =H39 -> 3.56 | J39: =I39 -> 3.56 | K39: =J39 -> 3.56 | L39: =K39 -> 3.56
B40: Other equity | C40: =20033.53/100 -> 200.3353 | D40: =28158.12/100 -> 281.5812 | E40: =35238.17/100 -> 352.3817 | F40: =62321.62/100 -> 623.2162 | G40: 863.96 | H40: =G40+'INCOME STATEMENT'!I31 -> 1031.4641 | I40: =H40+'INCOME STATEMENT'!J31 -> 1238.4207 | J40: =I40+'INCOME STATEMENT'!K31 -> 1499.8939 | K40: =J40+'INCOME STATEMENT'!L31 -> 1831.5298 | L40: =K40+'INCOME STATEMENT'!M31 -> 2253.4175
B41: Total equity | C41: =SUM(C38:C40) -> 221.5334 | D41: =SUM(D38:D40) -> 304.1298 | E41: =SUM(E38:E40) -> 374.9303 | F41: =SUM(F38:F40) -> 646.1309 | G41: =SUM(G38:G40) -> 891.02 | H41: =SUM(H38:H40) -> 1058.5241 | I41: =SUM(I38:I40) -> 1265.4807 | J41: =SUM(J38:J40) -> 1526.9539 | ... L41: =SUM(L38:L40) -> 2280.4775
B43: Liabilities
B44: Non-current liabilities
B45: Financial liabilities - Borrowings (Non-current) | C45: =18652.69/100 -> 186.5269 | D45: =25430.83/100 -> 254.3083 | E45: =38195.45/100 -> 381.9545 | F45: =49519.56/100 -> 495.1956 | G45: 618.62 | H45: ='DEBT SCHEDULE'!I9 -> 886.33044 | I45: ='DEBT SCHEDULE'!J9 -> 1151.2119 | J45: ='DEBT SCHEDULE'!K9 -> 1493.5401 | K45: ='DEBT SCHEDULE'!L9 -> 1935.6734 | L45: ='DEBT SCHEDULE'!M9 -> 2506.4058
B46: Lease liabilities (Non-current) | C46: 0 | D46: =2255.51 /100 -> 22.5551 | E46: =2024.39/100 -> 20.2439 | F46: =4058.72/100 -> 40.5872 | G46: 36.93 | H46: =G46 -> 36.93 | I46: =H46 -> 36.93 | J46: =I46 -> 36.93 | K46: =J46 -> 36.93 | L46: =K46 -> 36.93
B47: Provisions (Non-current) | C47: 0 | D47: 0 | E47: =537.2/100 -> 5.372 | F47: =1295.57/100 -> 12.9557 | G47: 25.71 | H47: =G47 -> 25.71 | I47: =H47 -> 25.71 | J47: =I47 -> 25.71 | K47: =J47 -> 25.71 | L47: =K47 -> 25.71
B48: Employee benefits obligation (Non-current) | C48: =191.01/100 -> 1.9101 | D48: =283.21/100 -> 2.8321 | E48: 0 | F48: 0 | G48: 0 | H48: =G48 -> 0 | I48: =H48 -> 0 | J48: =I48 -> 0 | K48: =J48 -> 0 | L48: =K48 -> 0
B49: Deferred tax liabilities (net) | C49: =1793.09 /100 -> 17.9309 | D49: =2670.59/100 -> 26.7059 | E49: =4775.91/100 -> 47.7591 | F49: =4133.45/100 -> 41.3345 | G49: 45.62 | H49: =G49 -> 45.62 | I49: =H49 -> 45.62 | J49: =I49 -> 45.62 | K49: =J49 -> 45.62 | L49: =K49 -> 45.62
...

Sheet FA SCHEDULE
C3: Ftr = Sales/total depreciable assets
C4: Total depreciable assets = Sales/ftr
B6: Particulars (Rs in Crores) | C6: 2021A | D6: 2022A | E6: 2023A | F6: 2024A | G6: 2025A | H6: 2026F | I6: 2027F | J6: 2028F | K6: 2029F | L6: 2030F
B8: Total Depreciation & Amortization
B9: Depreciation | C9: 16.6613 | D9: 24.0663 | E9: 37.3803 | F9: 54.674 | G9: 69.82
B10: Amortization | C10: 0.5343 | D10: 0.4425 | E10: 0.0249 | F10: 0.124 | G10: 1.6
B12: TANGIBLE FIXED ASSETS
B13: Opening PPE & Capital WIP | C13: 0 | D13: =C17 -> 323.8151 | E13: =D17 -> 481.776 | F13: =E17 -> 644.381 | G13: =F17 -> 855.2682 | H13: =G17 -> 1047.63 | I13: =H17 -> 1200.5451 | J13: =I17 -> 1541.0873 | K13: =J17 -> 1979.032 | L13: =K17 -> 2542.2758
B14: (+)Capex (Net addition) | C14: =C15+C13 -> 307.1538 | D14: =D15+D13 -> 781.5248 | E14: =E15+E13 -> 1088.7767 | F14: =F15+F13 -> 1444.9752 | G14: =G15+G13 -> 1833.0782 | H14: =H15-H13 -> 243.0679 | I14: =I15-I13 -> 456.26747 | J14: =J15-J13 -> 586.55666 | K14: =K15-K13 -> 754.15145 | L14: =L15-L13 -> 969.76191
B15: Total Depreciable PPE & WIP | C15: =C17-C16 -> 307.1538 | D15: =D17-D16 -> 457.7097 | E15: =E17-E16 -> 607.0007 | F15: =F17-F16 -> 800.5942 | G15: =G17-G16 -> 977.81 | H15: ='INCOME STATEMENT'!I8/'FA SCHEDULE'!H20 -> 1290.6979 | I15: ='INCOME STATEMENT'!J8/'FA SCHEDULE'!I20 -> 1656.8125 | J15: ='INCOME STATEMENT'!K8/'FA SCHEDULE'!J20 -> 2127.644 | K15: ='INCOME STATEMENT'!L8/'FA SCHEDULE'!K20 -> 2733.1835 | L15: ='INCOME STATEMENT'!M8/'FA SCHEDULE'!L20 -> 3512.0377
B16: (-)Depreciation | C16: =C9 -> 16.6613 | D16: =D9 -> 24.0663 | E16: =E9 -> 37.3803 | F16: =F9 -> 54.674 | G16: =G9 -> 69.82 | H16: =H19*H15 -> 90.152823 | I16: =I19*I15 -> 115.72524 | J16: =J19*J15 -> 148.61193 | K16: =K19*K15 -> 190.90773 | L16: =L19*L15 -> 245.30923
B17: Closing PPE & Capital WIP | C17: ='BALANCE SHEET'!C9+'BALANCE SHEET'!C11 -> 323.8151 | D17: ='BALANCE SHEET'!D9+'BALANCE SHEET'!D11 -> 481.776 | E17: ='BALANCE SHEET'!E9+'BALANCE SHEET'!E11 -> 644.381 | F17: ='BALANCE SHEET'!F9+'BALANCE SHEET'!F11 -> 855.2682 | G17: ='BALANCE SHEET'!G9+'BALANCE SHEET'!G11 -> 1047.63 | H17: =H15-H16 -> 1200.5451 | I17: =I15-I16 -> 1541.0873 | J17: =J15-J16 -> 1979.032 | K17: =K15-K16 -> 2542.2758 | L17: =L15-L16 -> 3266.7284
B19: Depreciation as % of Total Depreciable TFA | C19: =C16/C15 -> 0.05424416 | D19: =D16/D15 -> 0.052579834 | E19: =E16/E15 -> 0.061581972 | F19: =F16/F15 -> 0.068291776 | G19: =G16/G15 -> 0.071404465 | H19: =AVERAGE(F19:G19) -> 0.069848121 | I19: 0.069848121 | J19: 0.069848121 | K19: 0.069848121 | L19: 0.069848121
B20: Fixed Asset Turnover Ratio (Sales/TDA) | C20: ='INCOME STATEMENT'!D8/'FA SCHEDULE'!C15 -> 4.513533 | D20: ='INCOME STATEMENT'!E8/'FA SCHEDULE'!D15 -> 4.4572027 | E20: ='INCOME STATEMENT'!F8/'FA SCHEDULE'!E15 -> 4.2802761 | F20: ='INCOME STATEMENT'!G8/'FA SCHEDULE'!F15 -> 3.4408349 | G20: ='INCOME STATEMENT'!H8/'FA SCHEDULE'!G15 -> 3.6452685 | H20: 3.5430517 | I20: 3.5430517 | J20: 3.5430517 | K20: 3.5430517 | L20: 3.5430517
B22: INTANGIBLE FIXED ASSETS
B23: Opening Intangibles | C23: 0 | D23: =C27 -> 0.5109 | E23: =D27 -> 0.067 | F23: =E27 -> 0.4431 | G23: =F27 -> 1.4564 | H23: =G27 -> 8.43 | I23: =H27 -> 14.98032 | J23: =I27 -> 20.751208 | K23: =J27 -> 25.835411 | L23: =K27 -> 30.314639
B24: Increase in Intangibles during the Year | C24: =C25-C23 -> 1.0452 | D24: =D25-D23 -> -0.0014 | E24: =E25-E23 -> 0.401 | F24: =F25-F23 -> 1.1373 | G24: =G25-G23 -> 8.5736 | H24: =G24 -> 8.5736 | I24: =H24 -> 8.5736 | J24: =I24 -> 8.5736 | K24: =J24 -> 8.5736 | L24: =K24 -> 8.5736
B25: Total Amortizable Intangibles | C25: =C27+C26 -> 1.0452 | D25: =D27+D26 -> 0.5095 | E25: =E27+E26 -> 0.468 | F25: =F27+F26 -> 1.5804 | G25: =G27+G26 -> 10.03 | H25: =H23+H24 -> 17.0036 | I25: =I23+I24 -> 23.55392 | J25: =J23+J24 -> 29.324808 | K25: =K23+K24 -> 34.409011 | L25: =L23+L24 -> 38.888239
B26: Amortization | C26: =C10 -> 0.5343 | D26: =D10 -> 0.4425 | E26: =E10 -> 0.0249 | F26: =F10 -> 0.124 | G26: =G10 -> 1.6 | H26: =H25*H29 -> 2.0232803 | I26: =I25*I29 -> 2.8027113 | J26: =J25*J29 -> 3.4893968 | K26: =K25*K29 -> 4.0943727 | L26: =L25*L29 -> 4.6273618
B27: Closing Intangibles | C27: ='BALANCE SHEET'!C13+'BALANCE SHEET'!C14 -> 0.5109 | D27: ='BALANCE SHEET'!D13+'BALANCE SHEET'!D14 -> 0.067 | E27: ='BALANCE SHEET'!E13+'BALANCE SHEET'!E14 -> 0.4431 | F27: ='BALANCE SHEET'!F13+'BALANCE SHEET'!F14 -> 1.4564 | G27: ='BALANCE SHEET'!G13+'BALANCE SHEET'!G14 -> 8.43 | H27: =H25-H26 -> 14.98032 | I27: =I25-I26 -> 20.751208 | J27: =J25-J26 -> 25.835411 | K27: =K25-K26 -> 30.314639 | L27: =L25-L26 -> 34.260877
B29: Amortization as % of Total Amortizable ITFA | C29: =C26/C25 -> 0.51119403 | D29: =D26/D25 -> 0.86849853 | E29: =E26/E25 -> 0.053205128 | F29: =F26/F25 -> 0.078461149 | G29: =G26/G25 -> 0.15952144 | H29: =AVERAGE(F29:G29) -> 0.11899129 | I29: 0.11899129 | J29: 0.11899129 | K29: 0.11899129 | L29: 0.11899129

Sheet CFS
B6: Particulars (Rs in Crores) | D6: 2021A | E6: 2022A | F6: 2023A | G6: 2024A | H6: 2025A | I6: 2026F | J6: 2027F | K6: 2028F | L6: 2029F | M6: 2030F
B8: Cash Flow Operating Activities
B9: Net Profit (Consolidated) | I9: ='INCOME STATEMENT'!I31 -> 167.50413 | J9: ='INCOME STATEMENT'!J31 -> 206.95653 | K9: ='INCOME STATEMENT'!K31 -> 261.47325 | L9: ='INCOME STATEMENT'!L31 -> 331.63589 | M9: ='INCOME STATEMENT'!M31 -> 421.88766
B10: Add Depreciation & Amortization | I10: ='INCOME STATEMENT'!I17 -> 92.176103 | J10: ='INCOME STATEMENT'!J17 -> 118.52795 | K10: ='INCOME STATEMENT'!K17 -> 152.10133 | L10: ='INCOME STATEMENT'!L17 -> 195.0021 | M10: ='INCOME STATEMENT'!M17 -> 249.93659
B11: Change in NWC | I11: =-ASSUMPTIONS!H80 -> -157.70634 | J11: =-ASSUMPTIONS!I80 -> -175.99637 | K11: =-ASSUMPTIONS!J80 -> -226.33518 | L11: =-ASSUMPTIONS!K80 -> -291.09122 | M11: =-ASSUMPTIONS!L80 -> -374.40598
B12: Cash Flow From Operating Activities | I12: =SUM(I9:I11) -> 101.9739 | J12: =SUM(J9:J11) -> 149.48811 | K12: =SUM(K9:K11) -> 187.2394 | L12: =SUM(L9:L11) -> 235.54676 | M12: =SUM(M9:M11) -> 297.41827
B14: Cash Flow Investing Activities
B15: Capex ( Capex - I in tangilbes ) | I15: ='FA SCHEDULE'!H14-'FA SCHEDULE'!H24 -> 234.4943 | J15: ='FA SCHEDULE'!I14-'FA SCHEDULE'!I24 -> 447.69387 | K15: ='FA SCHEDULE'!J14-'FA SCHEDULE'!J24 -> 577.98306 | L15: ='FA SCHEDULE'!K14-'FA SCHEDULE'!K24 -> 745.57785 | M15: ='FA SCHEDULE'!L14-'FA SCHEDULE'!L24 -> 961.18831
B16: Cash Flow from Investing Activities | I16: =-I15 -> -234.4943 | J16: =-J15 -> -447.69387 | K16: =-K15 -> -577.98306 | L16: =-L15 -> -745.57785 | M16: =-M15 -> -961.18831
B18: Pre Financing Cash ( Opening Cash+CFO+CFI ) | I18: =I27+I12+I16 -> -55.530402 | J18: =J27+J12+J16 -> -115.28538 | K18: =K27+K12+K16 -> -155.93676 | L18: =L27+L12+L16 -> -208.49698 | M18: =M27+M12+M16 -> -276.41762
B20: Cash Flow Financing Activities
B21: Net Borrowing | I21: =I22-(I18) -> 238.45078 | J21: =J22-(J18) -> 350.09228 | K21: =K22-(K18) -> 457.47087 | L21: =L22-(L18) -> 595.8494 | M21: =M22-(M18) -> 774.15087
B22: Net Borrowing (Plug to maintain Target Cash = 4% of Revenue) | I22: =4%*'INCOME STATEMENT'!I8 -> 182.92038 | J22: =4%*'INCOME STATEMENT'!J8 -> 234.8069 | K22: =4%*'INCOME STATEMENT'!K8 -> 301.53411 | L22: =4%*'INCOME STATEMENT'!L8 -> 387.35242 | M22: =4%*'INCOME STATEMENT'!M8 -> 497.73325
B23: Dividend Paid back | I23: 0 | J23: 0 | K23: 0 | L23: 0 | M23: 0
B24: Cash Flow from Financing Activities | I24: =I21+I23 -> 238.45078 | J24: =J21+J23 -> 350.09228 | K24: =K21+K23 -> 457.47087 | L24: =L21+L23 -> 595.8494 | M24: =M21+M23 -> 774.15087
B26: Net Changes in Cash (CFO+CFI+CFF) | I26: =I12+I16+I24 -> 105.93038 | J26: =J12+J16+J24 -> 51.886525 | K26: =K12+K16+K24 -> 66.727203 | L26: =L12+L16+L24 -> 85.818314 | M26: =M12+M16+M24 -> 110.38083
B27: Add Opening Cash | I27: ='BALANCE SHEET'!G27 -> 76.99 | J27: =I28 -> 182.92038 | K27: =J28 -> 234.8069 | L27: =K28 -> 301.53411 | M27: =L28 -> 387.35242
B28: Closing Cash Balance | I28: =SUM(I12+I16+I24+I27) -> 182.92038 | J28: =SUM(J12+J16+J24+J27) -> 234.8069 | K28: =SUM(K12+K16+K24+K27) -> 301.53411 | L28: =SUM(L12+L16+L24+L27) -> 387.35242 | M28: =SUM(M12+M16+M24+M27) -> 497.73325

Sheet DEBT SCHEDULE
C1: Previous Year = | E1: ST % = 236.78 / 855 ≈ 28%
E2: LT % = 619 / 855 ≈ 72%
C4: Total Debt (t) = Assets − (Equity + Non-debt liabilities)
B6: Particulars (Rs in Crores) | D6: 2021A | E6: 2022A | F6: 2023A | G6: 2024A | H6: 2025A | I6: 2026F | J6: 2027F | K6: 2028F | L6: 2029F | M6: 2030F
B8: Short term debt | D8: ='BALANCE SHEET'!C54 -> 0.1441 | E8: ='BALANCE SHEET'!D54 -> 72.9697 | F8: ='BALANCE SHEET'!E54 -> 109.3505 | G8: ='BALANCE SHEET'!F54 -> 190.7308 | H8: ='BALANCE SHEET'!G54 -> 236.78 | I8: =I11*28% -> 344.68406 | J8: =J11*28% -> 447.69351 | K8: =K11*28% -> 580.82114 | L8: =L11*28% -> 752.76187 | M8: =M11*28% -> 974.71336
B9: Long term debt | D9: ='BALANCE SHEET'!C45 -> 186.5269 | E9: ='BALANCE SHEET'!D45 -> 254.3083 | F9: ='BALANCE SHEET'!E45 -> 381.9545 | G9: ='BALANCE SHEET'!F45 -> 495.1956 | H9: ='BALANCE SHEET'!G45 -> 618.62 | I9: =I11*72% -> 886.33044 | J9: =J11*72% -> 1151.2119 | K9: =K11*72% -> 1493.5401 | L9: =L11*72% -> 1935.6734 | M9: =M11*72% -> 2506.4058
B11: Total Debt | D11: =SUM(D8:D9) -> 186.671 | E11: =SUM(E8:E9) -> 327.278 | F11: =SUM(F8:F9) -> 491.305 | G11: =SUM(G8:G9) -> 685.9264 | H11: =SUM(H8:H9) -> 855.4 | I11: ='BALANCE SHEET'!H34-('BALANCE SHEET'!H41+'BALANCE SHEET'!H46+'BALANCE SHEET'!H47+'BALANCE SHEET'!H48+'BALANCE SHEET'!H49+'BALANCE SHEET'!H50+'BALANCE SHEET'!H56+'BALANCE SHEET'!H57+'BALANCE SHEET'!H58+'BALANCE SHEET'!H59+'BALANCE SHEET'!H60+'BALANCE SHEET'!H61+'BALANCE SHEET'!H62) -> 1231.0145 | J11: ='BALANCE SHEET'!I34-('BALANCE SHEET'!I41+'BALANCE SHEET'!I46+'BALANCE SHEET'!I47+'BALANCE SHEET'!I48+'BALANCE SHEET'!I49+'BALANCE SHEET'!I50+'BALANCE SHEET'!I56+'BALANCE SHEET'!I57+'BALANCE SHEET'!I58+'BALANCE SHEET'!I59+'BALANCE SHEET'!I60+'BALANCE SHEET'!I61+'BALANCE SHEET'!I62) -> 1598.9054 | K11: ='BALANCE SHEET'!J34-('BALANCE SHEET'!J41+'BALANCE SHEET'!J46+'BALANCE SHEET'!J47+'BALANCE SHEET'!J48+'BALANCE SHEET'!J49+'BALANCE SHEET'!J50+'BALANCE SHEET'!J56+'BALANCE SHEET'!J57+'BALANCE SHEET'!J58+'BALANCE SHEET'!J59+'BALANCE SHEET'!J60+'BALANCE SHEET'!J61+'BALANCE SHEET'!J62) -> 2074.3612 | L11: ='BALANCE SHEET'!K34-('BALANCE SHEET'!K41+'BALANCE SHEET'!K46+'BALANCE SHEET'!K47+'BALANCE SHEET'!K48+'BALANCE SHEET'!K49+'BALANCE SHEET'!K50+'BALANCE SHEET'!K56+'BALANCE SHEET'!K57+'BALANCE SHEET'!K58+'BALANCE SHEET'!K59+'BALANCE SHEET'!K60+'BALANCE SHEET'!K61+'BALANCE SHEET'!K62) -> 2688.4353 | M11: ='BALANCE SHEET'!L34-('BALANCE SHEET'!L41+'BALANCE SHEET'!L46+'BALANCE SHEET'!L47+'BALANCE SHEET'!L48+'BALANCE SHEET'!L49+'BALANCE SHEET'!L50+'BALANCE SHEET'!L56+'BALANCE SHEET'!L57+'BALANCE SHEET'!L58+'BALANCE SHEET'!L59+'BALANCE SHEET'!L60+'BALANCE SHEET'!L61+'BALANCE SHEET'!L62) -> 3481.1191
B12: Average Debt | I12: =(I11+H11)/2 -> 1043.2073 | J12: =(J11+I11)/2 -> 1414.96 | K12: =(K11+J11)/2 -> 1836.6333 | L12: =(L11+K11)/2 -> 2381.3982 | M12: =(M11+L11)/2 -> 3084.7772
B13: Finance Cost | D13: ='INCOME STATEMENT'!D16 -> 18.6766 | E13: ='INCOME STATEMENT'!E16 -> 20.241 | F13: ='INCOME STATEMENT'!F16 -> 35.8019 | G13: ='INCOME STATEMENT'!G16 -> 56.6816 | H13: ='INCOME STATEMENT'!H16 -> 80.04 | I13: =I12*$I$14 -> 85.746167 | J13: =J12*$I$14 -> 116.30229 | K13: =K12*$I$14 -> 150.96163 | L13: =L12*$I$14 -> 195.73845 | M13: =M12*$I$14 -> 253.55251
B14: Interest Rate (Finance Cost as % of Total Debt) | D14: =D13/D11 -> 0.10005089 | E14: =E13/E11 -> 0.061846504 | F14: =F13/F11 -> 0.072871027 | G14: =G13/G11 -> 0.082635105 | H14: =H13/H11 -> 0.09357026 | I14: =AVERAGE(D14:H14) -> 0.082194757

Sheet WACC
B1: 5th May
B2: COMPS OF HINDUSTAN FOODS | C2: DEBT | D2: EQUITY | E2: DEBT% | F2: EQUITY%
B3: CCL Products (India) Ltd | C3: =55630.48 +125630.36+168.21+48.9/100 -> 181429.54 | D3: =1176* 13.35 -> 15699.6 | E3: =C3/SUM(C3:D3) -> 0.92035881 | F3: =D3/SUM(C3:D3) -> 0.079641194
B4: Mrs Bectors Food Specialities Ltd | C4: =608.7+704.52+ 487.58+ 39.7*0.1 -> 1804.77 | D4: =6.13*200 -> 1226 | E4: =C4/SUM(C4:D4) -> 0.59548234 | F4: =D4/SUM(C4:D4) -> 0.40451766
B5: Avanti Feeds | C5: =39.22+ 2.87/100 -> 39.2487 | D5: =13.62* 1326 -> 18060.12 | E5: =C5/SUM(C5:D5) -> 0.0021685121 | F5: =D5/SUM(C5:D5) -> 0.99783149
B6: Tasty Bite Eatables | C6: =195.78 + 71.19+ 384.41 + 73.34 *0.1 -> 658.714 | D6: =0.2566*7290 -> 1870.614 | E6: =C6/SUM(C6:D6) -> 0.26043044 | F6: =D6/SUM(C6:D6) -> 0.73956956
B7: Zydus Wellness Ltd | C7: =1850+ 14 + 19*0.1 -> 1865.9 | D7: =6.36*504 -> 3205.44 | E7: =C7/SUM(C7:D7) -> 0.36793037 | F7: =D7/SUM(C7:D7) -> 0.63206963
E8: =MEDIAN(E3:E7) -> 0.36793037 | F8: =MEDIAN(F3:F7) -> 0.63206963
E9: Target Capital Structure
B12: TAX RATE | C12: 0.25
B14: Cost of Debt (using historical Wgted Avg Interest Rate) | C14: COD = | D14: Wd*kd *(1-tax)+we*ke | G14: Cost of debt (using Synthetic Rating Method)
B16: Particulars | C16: Notes | D16: Value | G16: Particulars | H16: Notes | I16: Value
B17: Debt Borrowing Rate (%) | D17: ='DEBT SCHEDULE'!I14 -> 0.082194757 | G17: Risk-free Rate | I17: 0.06915 | K17: Government Bond Deal
G18: Synthetic Rating | I18: A3/A-
B19: Income Tax Rate (%) | D19: =C12 -> 0.25 | G19: Credit Spread | I19: 0.0089 | K19: Interest Coverage Ratio
B20: After-tax Cost of Debt (%) | D20: =D17*(1-D19) -> 0.061646068 | G20: Debt Borrowing Rate (%) | I20: =I17+I19 -> 0.07805 | K20: Base case: A2 / A → 0.78%
K21: Safer assumption: A3 / A- → 0.89%
G22: Income Tax Rate (%) | I22: =C12 -> 0.25
B23: ERP(HISTORICAL) | C23: ='REGRESSION BETA'!F5 -> 0.024824687 | G23: After-tax Cost of Debt (%) | I23: =I20*(1-I22) -> 0.0585375
B24: ERP(RATING BASED) | C24: 0.0708
B25: REGRESSION BETA | C25: ='REGRESSION BETA'!C8 -> 1.2985003
B26: COST OF EQUITY | C26: =I17+C25*(C24) -> 0.16108382
B27: WACC (REGRESSION)
B30: ERP(HISTORICAL) | C30: ='REGRESSION BETA'!F5 -> 0.024824687
B31: ERP(RATING BASED) | C31: 0.0708 | E31: Country Default Spreads and Risk Premiums
B32: BOTTOM UP BETA | C32: ='BOTTOM UP BETA'!E15 -> 0.43727126
B33: COST OF EQUITY | C33: =I17+C32*(C31) -> 0.10010881 | D33: = | E33: Wd*kd *(1-tax)+we*ke
B34: WACC (BOTTOM UP)

Sheet REGRESSION BETA
B2: COMPS OF HINDUSTAN FOODS | C2: REGRESSION BETA | E2: CAGR | F2: 0.093974687
B3: CCL Products (India) Ltd | C3: =SLOPE(M12:M219,I12:I219) -> 0.90235815 | E3: RRI | F3: =_xlfn.RRI(5,H219,H12) -> 0.093974687
B4: Mrs Bectors Food Specialities Ltd | C4: =SLOPE(Q12:Q219,I12:I219) -> 0.91098661 | E4: RFR | F4: =WACC!I17 -> 0.06915
B5: Avanti Feeds | C5: =SLOPE(U12:U219,I12:I219) -> 0.79005141 | E5: ERP | F5: =F3-F4 -> 0.024824687
B6: Tasty Bite Eatables | C6: =SLOPE(Y12:Y219,I12:I219) -> 0.62740784
B7: Zydus Wellness Ltd | C7: =SLOPE(AC12:AC219,I12:I219) -> 0.5364605
B8: Hindustan Foods Ltd | C8: =SLOPE(E12:E219,I12:I219) -> 1.2985003
C10: Hindustan Foods Ltd | G10: NIFTY 50 | K10: CCL Products (India) Ltd | O10: Mrs Bectors Food Specialities Ltd | S10: Avanti Feeds | W10: Tasty Bite Eatables | AA10: Zydus Wellness Ltd
C11: Date | D11: Price | E11: Return | G11: Date | H11: Price | I11: Return | K11: Date | L11: Price | M11: Return | O11: Date | P11: Price | Q11: Return | S11: Date | T11: Price | U11: Return | W11: Date | X11: Price | Y11: Return | AA11: Date | AB11: Price | AC11: Return
C12: 03/30/2025 | D12: 526.85 | E12: =D12/D13-1 -> -0.069744857 | G12: 45746 | H12: 22904.45 | I12: =H12/H13-1 -> -0.02614443 | K12: 03/30/2025 | L12: 550.8 | M12: =L12/L13-1 -> -0.0075675676 | O12: 03/30/2025 | P12: 300.95 | Q12: =P12/P13-1 -> 0.029663337 | S12: 03/30/2025 | T12: 719.7 | U12: =T12/T13-1 -> -0.21228041 | W12: 03/30/2025 | X12: 8004.25 | Y12: =X12/X13-1 -> -0.02615218 | AA12: 03/30/2025 | AB12: 339.44 | AC12: =AB12/AB13-1 -> 0.0099375186
C13: 03/23/2025 | D13: 566.35 | E13: =D13/D14-1 -> 0.019440194 | G13: 45739 | H13: 23519.35 | I13: =H13/H14-1 -> 0.0072354221 | K13: 03/23/2025 | L13: 555 | M13: =L13/L14-1 -> -0.064554188 | O13: 03/23/2025 | P13: 292.28 | Q13: =P13/P14-1 -> -0.063625296 | S13: 03/23/2025 | T13: 913.65 | U13: =T13/T14-1 -> -0.021683264 | W13: 03/23/2025 | X13: 8219.2 | Y13: =X13/X14-1 -> -0.06307744 | AA13: 03/23/2025 | AB13: 336.1 | AC13: =AB13/AB14-1 -> 0.007735668
C14: 03/16/2025 | D14: 555.55 | E14: =D14/D15-1 -> 0.039090994 | G14: 45732 | H14: 23350.4 | I14: =H14/H15-1 -> 0.042558891 | K14: 03/16/2025 | L14: 593.3 | M14: =L14/L15-1 -> 0.040147265 | O14: 03/16/2025 | P14: 312.14 | Q14: =P14/P15-1 -> 0.042377692 | S14: 03/16/2025 | T14: 933.9 | U14: =T14/T15-1 -> 0.10842087 | W14: 03/16/2025 | X14: 8772.55 | Y14: =X14/X15-1 -> 0.027387073 | AA14: 03/16/2025 | AB14: 333.52 | AC14: =AB14/AB15-1 -> 0.04814582
C15: 45903 | D15: 534.65 | E15: =D15/D16-1 -> 0.0089639555 | G15: 45725 | H15: 22397.2 | I15: =H15/H16-1 -> -0.0068861545 | K15: 45903 | L15: 570.4 | M15: =L15/L16-1 -> -0.047348643 | O15: 45903 | P15: 299.45 | Q15: =P15/P16-1 -> 0.047064583 | S15: 45903 | T15: 842.55 | U15: =T15/T16-1 -> 0.054901715 | W15: 45903 | X15: 8538.7 | Y15: =X15/X16-1 -> 0.0086647333 | AA15: 45903 | AB15: 318.2 | AC15: =AB15/AB16-1 -> -0.010110437
C16: 45691 | D16: 529.9 | E16: =D16/D17-1 -> 0.038205329 | G16: 45718 | H16: 22552.5 | I16: =H16/H17-1 -> 0.019335855 | K16: 45691 | L16: 598.75 | M16: =L16/L17-1 -> 0.031971734 | O16: 45691 | P16: 285.99 | Q16: =P16/P17-1 -> 0.082598327 | S16: 45691 | T16: 798.7 | U16: =T16/T17-1 -> 0.15310763 | W16: 45691 | X16: 8465.35 | Y16: =X16/X17-1 -> -0.03758548 | AA16: 45691 | AB16: 321.45 | AC16: =AB16/AB17-1 -> 0.029430603
C17: 02/23/2025 | D17: 510.4 | E17: =D17/D18-1 -> -0.083003953 | G17: 45711 | H17: 22124.7 | I17: =H17/H18-1 -> -0.029443891 | K17: 02/23/2025 | L17: 580.2 | M17: =L17/L18-1 -> -0.032435587 | O17: 02/23/2025 | P17: 264.17 | Q17: =P17/P18-1 -> -0.039835714 | S17: 02/23/2025 | T17: 692.65 | U17: =T17/T18-1 -> -0.043829376 | W17: 02/23/2025 | X17: 8795.95 | Y17: =X17/X18-1 -> -0.019753265 | AA17: 02/23/2025 | AB17: 312.26 | AC17: =AB17/AB18-1 -> -0.06106985
C18: 02/16/2025 | D18: 556.6 | E18: =D18/D19-1 -> 0.059584999 | G18: 45704 | H18: 22795.9 | I18: =H18/H19-1 -> -0.0058157157 | K18: 02/16/2025 | L18: 599.65 | M18: =L18/L19-1 -> 0.0020889037 | O18: 02/16/2025 | P18: 275.13 | Q18: =P18/P19-1 -> 0.012065477 | S18: 02/16/2025 | T18: 724.4 | U18: =T18/T19-1 -> 0.099241275 | W18: 02/16/2025 | X18: 8973.2 | Y18: =X18/X19-1 -> 0.0018421963 | AA18: 02/16/2025 | AB18: 332.57 | AC18: =AB18/AB19-1 -> -0.011767153
C19: 45902 | D19: 525.3 | E19: =D19/D20-1 -> -0.051890624 | G19: 45697 | H19: 22929.25 | I19: =H19/H20-1 -> -0.026770006 | K19: 45902 | L19: 598.4 | M19: =L19/L20-1 -> -0.085504699 | O19: 45902 | P19: 271.85 | Q19: =P19/P20-1 -> -0.079410769 | S19: 45902 | T19: 659 | U19: =T19/T20-1 -> -0.084849326 | W19: 45902 | X19: 8956.7 | Y19: =X19/X20-1 -> -0.10893236 | AA19: 45902 | AB19: 336.53 | AC19: =AB19/AB20-1 -> -0.060182082
C20: 45690 | D20: 554.05 | E20: =D20/D21-1 -> 0.093232044 | G20: 45690 | H20: 23559.95 | I20: =H20/H21-1 -> 0.0021928332 | K20: 45690 | L20: 654.35 | M20: =L20/L21-1 -> 0.052517291 | O20: 45690 | P20: 295.3 | Q20: =P20/P21-1 -> 0.0044559339 | S20: 45690 | T20: 720.1 | U20: =T20/T21-1 -> 0.017305926 | W20: 45690 | X20: 10051.65 | Y20: =X20/X21-1 -> 0.064539702 | AA20: 45690 | AB20: 358.08 | AC20: =AB20/AB21-1 -> -0.025022463
C21: 01/26/2025 | D21: 506.8 | E21: =D21/D22-1 -> 0.041619566 | G21: 45683 | H21: 23508.4 | I21: =H21/H22-1 -> 0.018023402 | K21: 01/26/2025 | L21: 621.7 | M21: =L21/L22-1 -> 0.017512275 | O21: 01/26/2025 | P21: 293.99 | Q21: =P21/P22-1 -> -0.011000471 | S21: 01/26/2025 | T21: 707.85 | U21: =T21/T22-1 -> 0.022092268 | W21: 01/26/2025 | X21: 9442.25 | Y21: =X21/X22-1 -> -0.046251824 | AA21: 01/26/2025 | AB21: 367.27 | AC21: =AB21/AB22-1 -> 0.022324287
C22: 01/19/2025 | D22: 486.55 | E22: =D22/D23-1 -> -0.014781816 | G22: 45676 | H22: 23092.2 | I22: =H22/H23-1 -> -0.0047838229 | K22: 01/19/2025 | L22: 611 | M22: =L22/L23-1 -> -0.040138245 | O22: 01/19/2025 | P22: 297.26 | Q22: =P22/P23-1 -> -0.002181867 | S22: 01/19/2025 | T22: 692.55 | U22: =T22/T23-1 -> 0.058216823 | W22: 01/19/2025 | X22: 9900.15 | Y22: =X22/X23-1 -> -0.020180027 | AA22: 01/19/2025 | AB22: 359.25 | AC22: =AB22/AB23-1 -> -0.042561697
C23: 45992 | D23: 493.85 | E23: =D23/D24-1 -> -0.0124975 | G23: 45669 | H23: 23203.2 | I23: =H23/H24-1 -> -0.0097432943 | K23: 45992 | L23: 636.55 | M23: =L23/L24-1 -> -0.032819266 | O23: 45992 | P23: 297.91 | Q23: =P23/P24-1 -> -0.045343844 | S23: 45992 | T23: 654.45 | U23: =T23/T24-1 -> 0.081914366 | W23: 45992 | X23: 10104.05 | Y23: =X23/X24-1 -> 0.035935634 | AA23: 45992 | AB23: 375.22 | AC23: =AB23/AB24-1 -> -0.012474997
C24: 45778 | D24: 500.1 | E24: =D24/D25-1 -> -0.037436243 | G24: 45662 | H24: 23431.5 | I24: =H24/H25-1 -> -0.02388069 | K24: 45778 | L24: 658.15 | M24: =L24/L25-1 -> -0.09420589 | O24: 45778 | P24: 312.06 | Q24: =P24/P25-1 -> -0.031170444 | S24: 45778 | T24: 604.9 | U24: =T24/T25-1 -> -0.1078829 | W24: 45778 | X24: 9753.55 | Y24: =X24/X25-1 -> -0.038983368 | AA24: 45778 | AB24: 379.96 | AC24: =AB24/AB25-1 -> -0.041303964
C25: 12/29/2024 | D25: 519.55 | E25: =D25/D26-1 -> 0.0087370158 | G25: 45655 | H25: 24004.75 | I25: =H25/H26-1 -> 0.0080353918 | K25: 12/29/2024 | L25: 726.6 | M25: =L25/L26-1 -> -0.0088664575 | O25: 12/29/2024 | P25: 322.1 | Q25: =P25/P26-1 -> -0.017897978 | S25: 12/29/2024 | T25: 678.05 | U25: =T25/T26-1 -> 0.10019471 | W25: 12/29/2024 | X25: 10149.2 | Y25: =X25/X26-1 -> 0.014382377 | AA25: 12/29/2024 | AB25: 396.33 | AC25: =AB25/AB26-1 -> 0.043770246
C26: 12/22/2024 | D26: 515.05 | E26: =D26/D27-1 -> -0.053825664 | G26: 45648 | H26: 23813.4 | I26: =H26/H27-1 -> 0.0095771065 | K26: 12/22/2024 | L26: 733.1 | M26: =L26/L27-1 -> -0.016567174 | O26: 12/22/2024 | P26: 327.97 | Q26: =P26/P27-1 -> 0.00067124333 | S26: 12/22/2024 | T26: 616.3 | U26: =T26/T27-1 -> -0.009721218 | W26: 12/22/2024 | X26: 10005.3 | Y26: =X26/X27-1 -> -0.0066716307 | AA26: 12/22/2024 | AB26: 379.71 | AC26: =AB26/AB27-1 -> -0.0066968373
C27: 12/15/2024 | D27: 544.35 | E27: =D27/D28-1 -> -0.014929425 | G27: 45641 | H27: 23587.5 | I27: =H27/H28-1 -> -0.047673841 | K27: 12/15/2024 | L27: 745.45 | M27: =L27/L28-1 -> -0.032197339 | O27: 12/15/2024 | P27: 327.75 | Q27: =P27/P28-1 -> -0.082189863 | S27: 12/15/2024 | T27: 622.35 | U27: =T27/T28-1 -> 0.00419524 | W27: 12/15/2024 | X27: 10072.5 | Y27: =X27/X28-1 -> -0.061661574 | AA27: 12/15/2024 | AB27: 382.27 | AC27: =AB27/AB28-1 -> -0.050001243
C28: 45516 | D28: 552.6 | E28: =D28/D29-1 -> -0.043116883 | G28: 45634 | H28: 24768.3 | I28: =H28/H29-1 -> 0.0036672637 | K28: 45516 | L28: 770.25 | M28: =L28/L29-1 -> -0.024073487 | O28: 45516 | P28: 357.1 | Q28: =P28/P29-1 -> -0.042010945 | S28: 45516 | T28: 619.75 | U28: =T28/T29-1 -> 0.020920847 | W28: 45516 | X28: 10734.4 | Y28: =X28/X29-1 -> -0.0015208241 | AA28: 45516 | AB28: 402.39 | AC28: =AB28/AB29-1 -> -0.017554568
C29: 45303 | D29: 577.5 | E29: =D29/D30-1 -> 0.041666667 | G29: 45627 | H29: 24677.8 | I29: =H29/H30-1 -> 0.022655411 | K29: 45303 | L29: 789.25 | M29: =L29/L30-1 -> -0.0027797081 | O29: 45303 | P29: 372.76 | Q29: =P29/P30-1 -> 0.02728325 | S29: 45303 | T29: 607.05 | U29: =T29/T30-1 -> 0.035479744 | W29: 45303 | X29: 10750.75 | Y29: =X29/X30-1 -> -0.0034205782 | AA29: 45303 | AB29: 409.58 | AC29: =AB29/AB30-1 -> 0.011333613
C30: 11/24/2024 | D30: 554.4 | E30: =D30/D31-1 -> 0.014270033 | G30: 45620 | H30: 24131.1 | I30: =H30/H31-1 -> 0.0093632685 | K30: 11/24/2024 | L30: 791.45 | M30: =L30/L31-1 -> 0.068732699 | O30: 11/24/2024 | P30: 362.86 | Q30: =P30/P31-1 -> 0.066576526 | S30: 11/24/2024 | T30: 586.25 | U30: =T30/T31-1 -> -0.015698455 | W30: 11/24/2024 | X30: 10787.65 | Y30: =X30/X31-1 -> 0.0048202759 | AA30: 11/24/2024 | AB30: 404.99 | AC30: =AB30/AB31-1 -> 0.056670232
C31: 11/17/2024 | D31: 546.6 | E31: =D31/D32-1 -> 0.0078362681 | G31: 45613 | H31: 23907.25 | I31: =H31/H32-1 -> 0.015916151 | K31: 11/17/2024 | L31: 740.55 | M31: =L31/L32-1 -> 0.065539568 | O31: 11/17/2024 | P31: 340.21 | Q31: =P31/P32-1 -> 0.042118483 | S31: 11/17/2024 | T31: 595.6 | U31: =T31/T32-1 -> 0.024511912 | W31: 11/17/2024 | X31: 10735.9 | Y31: =X31/X32-1 -> -0.11859216 | AA31: 11/17/2024 | AB31: 383.27 | AC31: =AB31/AB32-1 -> -0.022569622
C32: 45576 | D32: 542.35 | E32: =D32/D33-1 -> -0.072826737 | G32: 45606 | H32: 23532.7 | I32: =H32/H33-1 -> -0.025488442 | K32: 45576 | L32: 695 | M32: =L32/L33-1 -> 0.0047708544 | O32: 45576 | P32: 326.46 | Q32: =P32/P33-1 -> -0.098475643 | S32: 45576 | T32: 581.35 | U32: =T32/T33-1 -> 0.0051871704 | W32: 45576 | X32: 12180.4 | Y32: =X32/X33-1 -> -0.012345279 | AA32: 45576 | AB32: 392.12 | AC32: =AB32/AB33-1 -> 0.002736223
C33: 45362 | D33: 584.95 | E33: =D33/D34-1 -> -0.039490969 | G33: 45599 | H33: 24148.2 | I33: =H33/H34-1 -> -0.0064247758 | K33: 45362 | L33: 691.7 | M33: =L33/L34-1 -> 0.016533177 | O33: 45362 | P33: 362.12 | Q33: =P33/P34-1 -> -0.030779937 | S33: 45362 | T33: 578.35 | U33: =T33/T34-1 -> -0.022148956 | W33: 45362 | X33: 12332.65 | Y33: =X33/X34-1 -> 0.02080488 | AA33: 45362 | AB33: 391.05 | AC33: =AB33/AB34-1 -> 0.0031553024
C34: 10/27/2024 | D34: 609 | E34: =D34/D35-1 -> 0.069077504 | G34: 45592 | H34: 24304.35 | I34: =H34/H35-1 -> 0.0051094257 | K34: 10/27/2024 | L34: 680.45 | M34: =L34/L35-1 -> 0.079394036 | O34: 10/27/2024 | P34: 373.62 | Q34: =P34/P35-1 -> 0.10079255 | S34: 10/27/2024 | T34: 591.45 | U34: =T34/T35-1 -> 0.074386921 | W34: 10/27/2024 | X34: 12081.3 | Y34: =X34/X35-1 -> -0.012053612 | AA34: 10/27/2024 | AB34: 389.82 | AC34: =AB34/AB35-1 -> 0.083344913
C35: 10/20/2024 | D35: 569.65 | E35: =D35/D36-1 -> -0.091104906 | G35: 45585 | H35: 24180.8 | I35: =H35/H36-1 -> -0.027088141 | K35: 10/20/2024 | L35: 630.4 | M35: =L35/L36-1 -> -0.024978733 | O35: 10/20/2024 | P35: 339.41 | Q35: =P35/P36-1 -> -0.080862242 | S35: 10/20/2024 | T35: 550.5 | U35: =T35/T36-1 -> -0.11188191 | W35: 10/20/2024 | X35: 12228.7 | Y35: =X35/X36-1 -> -0.06935312 | AA35: 10/20/2024 | AB35: 359.83 | AC35: =AB35/AB36-1 -> -0.08276829
C36: 10/13/2024 | D36: 626.75 | E36: =D36/D37-1 -> -0.0030223495 | G36: 45578 | H36: 24854.05 | I36: =H36/H37-1 -> -0.0044143125 | K36: 10/13/2024 | L36: 646.55 | M36: =L36/L37-1 -> -0.038015176 | O36: 10/13/2024 | P36: 369.27 | Q36: =P36/P37-1 -> -0.00097394692 | S36: 10/13/2024 | T36: 619.85 | U36: =T36/T37-1 -> 0.015481651 | W36: 10/13/2024 | X36: 13140 | Y36: =X36/X37-1 -> 0.012689446 | AA36: 10/13/2024 | AB36: 392.3 | AC36: =AB36/AB37-1 -> 0.0026837061
C37: 45453 | D37: 628.65 | E37: =D37/D38-1 -> -0.0090636822 | G37: 45571 | H37: 24964.25 | I37: =H37/H38-1 -> -0.0020128245 | K37: 45453 | L37: 672.1 | M37: =L37/L38-1 -> 0.0084021005 | O37: 45453 | P37: 369.63 | Q37: =P37/P38-1 -> 0.0047023648 | S37: 45453 | T37: 610.4 | U37: =T37/T38-1 -> 0.0051873199 | W37: 45453 | X37: 12975.35 | Y37: =X37/X38-1 -> 0.036311868 | AA37: 45453 | AB37: 391.25 | AC37: =AB37/AB38-1 -> 0.0037971111
C38: 09/29/2024 | D38: 634.4 | E38: =D38/D39-1 -> -0.060704768 | G38: 45564 | H38: 25014.6 | I38: =H38/H39-1 -> -0.044476574 | K38: 09/29/2024 | L38: 666.5 | M38: =L38/L39-1 -> -0.045949041 | O38: 09/29/2024 | P38: 367.9 | Q38: =P38/P39-1 -> -0.058573658 | S38: 09/29/2024 | T38: 607.25 | U38: =T38/T39-1 -> -0.018109791 | W38: 09/29/2024 | X38: 12520.7 | Y38: =X38/X39-1 -> -0.019518479 | AA38: 09/29/2024 | AB38: 389.77 | AC38: =AB38/AB39-1 -> -0.031867859
C39: 09/22/2024 | D39: 675.4 | E39: =D39/D40-1 -> 0.036684574 | G39: 45557 | H39: 26178.95 | I39: =H39/H40-1 -> 0.015044037 | K39: 09/22/2024 | L39: 698.6 | M39: =L39/L40-1 -> -0.077694897 | O39: 09/22/2024 | P39: 390.79 | Q39: =P39/P40-1 -> -0.076452238 | S39: 09/22/2024 | T39: 618.45 | U39: =T39/T40-1 -> -0.080029751 | W39: 09/22/2024 | X39: 12769.95 | Y39: =X39/X40-1 -> -0.040625211 | AA39: 09/22/2024 | AB39: 402.6 | AC39: =AB39/AB40-1 -> -0.032513878
C40: 09/15/2024 | D40: 651.5 | E40: =D40/D41-1 -> 0.14720902 | G40: 45550 | H40: 25790.95 | I40: =H40/H41-1 -> 0.017133674 | K40: 09/15/2024 | L40: 757.45 | M40: =L40/L41-1 -> 0.038242752 | O40: 09/15/2024 | P40: 423.14 | Q40: =P40/P41-1 -> 0.13652601 | S40: 09/15/2024 | T40: 672.25 | U40: =T40/T41-1 -> -0.0040002963 | W40: 09/15/2024 | X40: 13310.7 | Y40: =X40/X41-1 -> 0.00038329726 | AA40: 09/15/2024 | AB40: 416.13 | AC40: =AB40/AB41-1 -> -0.057911299
C41: 45513 | D41: 567.9 | E41: =D41/D42-1 -> -0.013463042 | G41: 45543 | H41: 25356.5 | I41: =H41/H42-1 -> 0.020294019 | K41: 45513 | L41: 729.55 | M41: =L41/L42-1 -> -0.039560295 | O41: 45513 | P41: 372.31 | Q41: =P41/P42-1 -> 0.030701512 | S41: 45513 | T41: 674.95 | U41: =T41/T42-1 -> 0.013971306 | W41: 45513 | X41: 13305.6 | Y41: =X41/X42-1 -> -0.038664812 | AA41: 45513 | AB41: 441.71 | AC41: =AB41/AB42-1 -> -0.020077203
C42: 45300 | D42: 575.65 | E42: =D42/D43-1 -> -0.0077566147 | G42: 45536 | H42: 24852.15 | I42: =H42/H43-1 -> -0.015206511 | K42: 45300 | L42: 759.6 | M42: =L42/L43-1 -> 0.0545606 | O42: 45300 | P42: 361.22 | Q42: =P42/P43-1 -> 0.12284737 | S42: 45300 | T42: 665.65 | U42: =T42/T43-1 -> -0.018649565 | W42: 45300 | X42: 13840.75 | Y42: =X42/X43-1 -> -0.010413688 | AA42: 45300 | AB42: 450.76 | AC42: =AB42/AB43-1 -> -0.018059035
...

Sheet BOTTOM UP BETA
B2: COMPS OF HINDUSTAN FOODS | C2: REGRESSION BETA | D2: DEBT% | E2: EQUITY% | F2: DFL | G2: UNLIVER
B3: CCL Products (India) Ltd | C3: 0.90235815 | D3: 0.92035881 | E3: 0.079641194 | F3: =1+(1-$C$10)*(D3/E3) -> 9.667237 | G3: =C3/F3 -> 0.093341887
B4: Mrs Bectors Food Specialities Ltd | C4: 0.91098661 | D4: 0.59548234 | E4: 0.40451766 | F4: =1+(1-$C$10)*(D4/E4) -> 2.10406 | G4: =C4/F4 -> 0.43296609
B5: Avanti Feeds | C5: 0.79005141 | D5: 0.0021685121 | E5: 0.99783149 | F5: =1+(1-$C$10)*(D5/E5) -> 1.0016299 | G5: =C5/F5 -> 0.78876579
B6: Tasty Bite Eatables | C6: 0.62740784 | D6: 0.26043044 | E6: 0.73956956 | F6: =1+(1-$C$10)*(D6/E6) -> 1.2641034 | G6: =C6/F6 -> 0.49632636
B7: Zydus Wellness Ltd | C7: 0.5364605 | D7: 0.36793037 | E7: 0.63206963 | F7: =1+(1-$C$10)*(D7/E7) -> 1.4365781 | G7: =C7/F7 -> 0.3734294 | H7: =AVERAGE(G3:G7) -> 0.4369659
B10: TAX RATE | C10: 0.25
B12: Debt % | C12: CY = | D12: =364.52 +2.35+141.58 +1.07 -> 509.52 | E12: =D12/SUM(D12:D13) -> 0.00093087749
B13: Equity % | C13: CY = | D13: =2327*235 -> 546845 | E13: =D13/SUM(D12:D13) -> 0.99906912
B14: DFL | E14: =1+(1-C10)*(D12/D13) -> 1.0006988
B15: BOTTOM UP BETA | E15: =E14*H7 -> 0.43727126
B16: REGRESSION BETA | E16: ='REGRESSION BETA'!C8 -> 1.2985003

Sheet DCF VALUATION
B2: Valuation Date | C2: =DATE(2025,3,31) -> 45747 | E2: REGRESSION BETA
B3: First projection date | C3: =DATE(2026,3,31) -> 46112 | E3: BOTTOM UP BETA
B5: BOTTOM UP BETA
B6: COST OF EQUITY | D6: {=_xlfn.IFS(B5=E2,WACC!C26,'DCF VALUATION'!B5='DCF VALUATION'!E3,WACC!C33)} -> 0.10010881
B7: WEIGHT OF EQUITY | D7: =WACC!F8 -> 0.63206963
B8: COST OF DEBT | D8: =WACC!I23 -> 0.0585375
B9: WEIGHT OF DEBT | D9: =WACC!E8 -> 0.36793037
B10: WACC | D10: =D6*D7+D8*D9 -> 0.08481346
C14: =_xlfn.DAYS(C3,C2)/365 -> 1 | D14: =1+C14 -> 2 | E14: =1+D14 -> 3 | F14: =1+E14 -> 4 | G14: =1+F14 -> 5 | I14: Terminal Year Normalisation
B15: Particulars | C15: 2026F | D15: 2027F | E15: 2028F | F15: 2029F | G15: 2030F | I15: Year | J15: 2030 | L15: ` | P15: Gordon Growth Method | R15: SENSITIVITY ANALYSIS
B16: EBIT | C16: ='INCOME STATEMENT'!I23+'INCOME STATEMENT'!I16 -> 304.57838 | D16: ='INCOME STATEMENT'!J23+'INCOME STATEMENT'!J16 -> 386.67624 | E16: ='INCOME STATEMENT'!K23+'INCOME STATEMENT'!K16 -> 492.55778 | F16: ='INCOME STATEMENT'!L23+'INCOME STATEMENT'!L16 -> 628.99709 | G16: ='INCOME STATEMENT'!M23+'INCOME STATEMENT'!M16 -> 804.71866 | I16: EBIT | J16: =G16 -> 804.71866
B17: TAX RATE | C17: =-'INCOME STATEMENT'!I30 -> -51.328075 | D17: =-'INCOME STATEMENT'!J30 -> -63.417422 | E17: =-'INCOME STATEMENT'!K30 -> -80.122908 | F17: =-'INCOME STATEMENT'!L30 -> -101.62275 | G17: =-'INCOME STATEMENT'!M30 -> -129.27849 | I17: NOPAT | J17: =G18 -> 675.44017 | L17: =C53 -> 761.94398 | M17: 0.02 | N17: 0.025 | O17: 0.03 | P17: 0.035 | Q17: 0.04 | R17: 0.045 | S17: 0.05 | T17: 0.055 | U17: 0.06 | V17: 0.065
B18: NOPAT | C18: =SUM(C16:C17) -> 253.2503 | D18: =SUM(D16:D17) -> 323.25882 | E18: =SUM(E16:E17) -> 412.43488 | F18: =SUM(F16:F17) -> 527.37434 | G18: =SUM(G16:G17) -> 675.44017 | I18: Terminal Reinvestment | J18: =J17*J24 -> 41.254257 | L18: 0.06 | M18: 992.11205 | N18: 1139.8312 | O18: 1336.7901 | P18: 1612.5325 | Q18: 2026.1461 | R18: 2715.5022 | S18: 4094.2143 | T18: 8230.3507 | U18: #DIV/0! | V18: -8314.1948
B19: (+) D&A | C19: ='INCOME STATEMENT'!I17 -> 92.176103 | D19: ='INCOME STATEMENT'!J17 -> 118.52795 | E19: ='INCOME STATEMENT'!K17 -> 152.10133 | F19: ='INCOME STATEMENT'!L17 -> 195.0021 | G19: ='INCOME STATEMENT'!M17 -> 249.93659 | I19: Terminal FCFF | J19: =J17-J18 -> 634.18591 | L19: 0.065 | M19: 851.98411 | N19: 963.78669 | O19: 1107.5329 | P19: 1299.1944 | Q19: 1567.5206 | R19: 1970.0099 | S19: 2640.8254 | T19: 3982.4564 | U19: 8007.3494 | V19: #DIV/0!
